<?xml version="1.0" encoding="utf-8"?>
<robot name="head-full">
  <!-- [URDF-WRITER] Generated on 2026-04-14 16:08:19 -->

  <!-- [URDF-WRITER] from module [_fixed-base] -->

  <!-- this link makes the robot fixed-base in RAISIM -->
  <link name="world"></link>

  <link name="base"></link>

  <joint name="base_fix" type="fixed">
    <origin xyz="0 0 0.8" rpy="0 0 0"/>
    <parent link="world" />
    <child link="base" />
    <axis xyz="0 0 0" />
  </joint>


  <!-- [URDF-WRITER] from module [head] -->

  <link name="HEAD_base">
    <!-- edited with custom script -->
    <inertial>
      <origin 
        xyz="-0.00013000000000000002 6e-05 -0.01956"
        rpy="0 0 0" />
      <mass value="0.22691" />
      <inertia
        ixx="6.726676e-05"
        ixy="-2.4361e-07"
        ixz="-6.3156e-07"
        iyy="6.666816e-05"
        iyz="6.418000000000001e-08"
        izz="7.244472e-05" />
    </inertial>
    <visual>
      <origin
        xyz="0 0 0"
        rpy="0 0 0" />
      <geometry>
        <mesh filename="../meshes/HEAD_base.STL" />
      </geometry>
      <material name="">
        <color rgba="0.898039215686275 0.917647058823529 0.929411764705882 1" />
      </material>
    </visual>
    <!-- <collision>
      <origin
        xyz="0 0 0"
        rpy="0 0 0" />
      <geometry>
        <mesh filename="../meshes/HEAD_base.STL" />
      </geometry>
    </collision> -->
  </link>

  <joint name="HEAD_fix" type="fixed">
    <origin xyz="0 0 0" rpy="0 0 0"/>
    <parent link="base" />
    <child link="HEAD_base" />
    <axis xyz="0 0 0" />
  </joint>

  <link name="HEAD_neck">
    <!-- edited with custom script -->
    <inertial>
    <origin
        xyz="-0.00621 -0.00059 0.09247"
        rpy="0 0 0" />
    <mass value="0.38718" />
    <inertia
        ixx="0.00084209162"
        ixy="1.78477e-06"
        ixz="-3.73364e-06"
        iyy="0.00090124031"
        iyz="6.43932e-06"
        izz="0.00015094396" />
    </inertial>
    <visual>
      <origin
        xyz="0 0 0"
        rpy="0 0 0" />
      <geometry>
        <mesh filename="../meshes/HEAD_neck.STL" />
      </geometry>
      <material name="">
        <color rgba="0.898039215686275 0.917647058823529 0.929411764705882 1" />
      </material>
    </visual>
    <!-- <collision>
      <origin
        xyz="0 0 0"
        rpy="0 0 0" />
      <geometry>
        <mesh filename="../meshes/HEAD_neck.STL" />
      </geometry>
    </collision> -->
  </link>
  <joint name="HEAD1_pan" type="revolute">
    <origin
      xyz="0 0 0"
      rpy="0 0 0" />
    <parent link="HEAD_base" />
    <child link="HEAD_neck" />
    <axis
      xyz="0 0 -1" />
    <limit
      lower="-1.5"
      upper="1.5"
      effort="1.57"
      velocity="390" />
  </joint>
  <link name="HEAD_chin">
    <!-- edited with custom script -->
    <inertial>
    <origin
        xyz="0.00292 -0.00883 -0.01141"
        rpy="0 0 0" />
    <mass value="0.06976" />
    <inertia
        ixx="4.2354910000000004e-05"
        ixy="-1.650247e-05"
        ixz="3.6080700000000003e-06"
        iyy="6.330044e-05"
        iyz="-3.7977e-07"
        izz="6.109326e-05" />
    </inertial>
    <visual>
      <origin
        xyz="0 0 0"
        rpy="0 0 0" />
      <geometry>
        <mesh filename="../meshes/HEAD_chin.STL" />
      </geometry>
      <material name="">
        <color rgba="0.752941176470588 0.752941176470588 0.752941176470588 1" />
      </material>
    </visual>
    <!-- <collision>
      <origin
        xyz="0 0 0"
        rpy="0 0 0" />
      <geometry>
        <mesh filename="../meshes/HEAD_chin.STL" />
      </geometry>
    </collision> -->
  </link>
  <joint name="HEAD2_tilt" type="revolute">
    <origin
      xyz="0 0.0186 0.12"
      rpy="-1.5708 0 0" />
    <parent link="HEAD_neck" />
    <child link="HEAD_chin" />
    <axis
      xyz="0 0 -1" />
    <limit
      lower="-1.0472"
      upper="0.83776"
      effort="1.57"
      velocity="390" />
  </joint>

  <!-- [URDF-WRITER] from module [head-face] -->

  <link name="HEAD_face">
    <!-- edited with custom script -->
    <inertial>
    <origin
        xyz="-0.011550000000000001 -0.02876 -0.01864"
        rpy="0 0 0" />
    <mass value="0.18813" />
    <inertia
        ixx="0.0006845556"
        ixy="-7.591147e-05"
        ixz="1.6041e-07"
        iyy="0.0010570050700000001"
        iyz="2.1685e-07"
        izz="0.00072350371" />
    </inertial>
    <visual>
      <origin
        xyz="0 0 0"
        rpy="0 0 0" />
      <geometry>
        <mesh filename="../meshes/HEAD_face.STL" />
      </geometry>
      <material name="">
        <color rgba="0.250980392156863 0.250980392156863 0.250980392156863 1" />
      </material>
    </visual>
    <!-- <collision>
      <origin
        xyz="0 0 0"
        rpy="0 0 0" />
      <geometry>
        <mesh filename="../meshes/HEAD_face.STL" />
      </geometry>
    </collision> -->
  </link>
  <joint name="HEAD_face_fixed" type="fixed">
    <origin
      xyz="0 0 0"
      rpy="0 0 0" />
    <parent link="HEAD_chin" />
    <child link="HEAD_face" />
    <axis
      xyz="0 0 0" />
  </joint>

  <!-- [URDF-WRITER] from module [head-sensor_d455] -->

  <link name="HEAD_d455">
    <!-- edited with custom script -->
    <inertial>
    <origin
        xyz="0.01298 5e-05 -0.00014000000000000001"
        rpy="0 0 0" />
    <mass value="0.12" />
    <inertia
        ixx="0.00014290851000000002"
        ixy="3.955e-08"
        ixz="-1.4216e-07"
        iyy="1.328332e-05"
        iyz="6.73e-08"
        izz="0.00014208451" />
    </inertial>
    <visual>
      <origin
        xyz="0 0 0"
        rpy="0 0 0" />
      <geometry>
        <mesh filename="../meshes/HEAD_d455.STL" />
      </geometry>
      <material name="">
        <color rgba="0.792156862745098 0.819607843137255 0.933333333333333 1" />
      </material>
    </visual>
    <!-- <collision>
      <origin
        xyz="0 0 0"
        rpy="0 0 0" />
      <geometry>
        <mesh filename="../meshes/HEAD_d455.STL" />
      </geometry>
    </collision> -->
  </link>
  <joint name="HEAD_d455_fixed" type="fixed">
    <origin
      xyz="0.042 0 -0.0186"
      rpy="1.5708 0 0" />
    <parent link="HEAD_chin" />
    <child link="HEAD_d455" />
    <axis
      xyz="0 0 0" />
  </joint>

  <!-- [URDF-WRITER] from module [head-sensor_mid360] -->

  <link name="HEAD_mid360">
    <!-- edited with custom script -->
    <inertial>
    <origin
        xyz="-0.0002 -1e-05 0.02203"
        rpy="0 0 0" />
    <mass value="0.265" />
    <inertia
        ixx="0.00012374566"
        ixy="-1.102e-08"
        ixz="-1.964e-08"
        iyy="0.00013334891"
        iyz="-3.4840000000000006e-08"
        izz="0.0001322739" />
    </inertial>
    <visual>
      <origin
        xyz="0 0 0"
        rpy="0 0 0" />
      <geometry>
        <mesh filename="../meshes/HEAD_mid360.STL" />
      </geometry>
      <material name="">
        <color rgba="0.792156862745098 0.819607843137255 0.933333333333333 1" />
      </material>
    </visual>
    <!-- <collision>
      <origin
        xyz="0 0 0"
        rpy="0 0 0" />
      <geometry>
        <mesh filename="../meshes/HEAD_mid360.STL" />
      </geometry>
    </collision> -->
  </link>
  <joint name="HEAD_mid360_fixed" type="fixed">
    <origin
      xyz="-0.025 -0.042 -0.0186"
      rpy="1.5708 0 0" />
    <parent link="HEAD_chin" />
    <child link="HEAD_mid360" />
    <axis
      xyz="0 0 0" />
  </joint>

</robot>
